Workbook

Sheet VENTA Y GASTO
B2: PREVISIÓN DE VENTAS DEL PRIMER AÑO | L2: Precio de venta x unidades vendidas (€) | O2: Estimación de ventas (Media mensual) | R2: Estimación de ventas (Media anual) | U2: Precio/ud (en función
A3: MES | B3: Móviles | C3: Auriculares | D3: Ordenadores | E3: Altavoces | F3: Tabletas | G3: Relojes | K3: PRODUCTO | L3: AÑO 1 | M3: AÑO 2 | N3: AÑO 3 | O3: AÑO 1 | P3: AÑO 2 | Q3: AÑO 3 | R3: AÑO 1 | S3: AÑO 2 | T3: AÑO 3 | U3: de su precio de fábrica)
A4: 1 | B4: 88 | C4: 71 | D4: 51 | E4: 49 | F4: 44 | G4: 37 | K4: Móviles | L4: =T24*R4 -> 756000 | M4: =T24*S4 -> 1152000 | N4: =T24*T4 -> 1908000 | O4: 105 | P4: 160 | Q4: 265 | R4: =O4*12 -> 1260 | S4: =P4*12 -> 1920 | T4: =Q4*12 -> 3180 | U4: 40%-60%
A5: 2 | B5: 91 | C5: 74 | D5: 54 | E5: 53 | F5: 48 | G5: 38 | K5: Auriculares | L5: =T25*R5 -> 270300 | M5: =T25*S5 -> 318000 | N5: =T25*T5 -> 413400 | O5: 85 | P5: 100 | Q5: 130 | R5: =O5*12 -> 1020 | S5: =P5*12 -> 1200 | T5: =Q5*12 -> 1560 | U5: 0.5
A6: 3 | B6: 88 | C6: 78 | D6: 57 | E6: 60 | F6: 51 | G6: 49 | K6: Ordenadores | L6: =T26*R6 -> 608400 | M6: =T26*S6 -> 889200 | N6: =T26*T6 -> 1310400 | O6: 65 | P6: 95 | Q6: 140 | R6: =O6*12 -> 780 | S6: =P6*12 -> 1140 | T6: =Q6*12 -> 1680 | U6: 0.65
A7: 4 | B7: 89 | C7: 88 | D7: 59 | E7: 63 | F7: 53 | G7: 50 | K7: Altavoces | L7: =T27*R7 -> 156000 | M7: =T27*S7 -> 204000 | N7: =T27*T7 -> 252000 | O7: 65 | P7: 85 | Q7: 105 | R7: =O7*12 -> 780 | S7: =P7*12 -> 1020 | T7: =Q7*12 -> 1260 | U7: 0.4
A8: 5 | B8: 91 | C8: 84 | D8: 61 | E8: 74 | F8: 57 | G8: 48 | K8: Tabletas | L8: =T28*R8 -> 188100 | M8: =T28*S8 -> 239400 | N8: =T28*T8 -> 342000 | O8: 55 | P8: 70 | Q8: 100 | R8: =O8*12 -> 660 | S8: =P8*12 -> 840 | T8: =Q8*12 -> 1200 | U8: 0.5
A9: 6 | B9: 123 | C9: 92 | D9: 74 | E9: 72 | F9: 63 | G9: 57 | K9: Relojes | L9: =T29*R9 -> 174000 | M9: =T29*S9 -> 226200 | N9: =T29*T9 -> 295800 | O9: 50 | P9: 65 | Q9: 85 | R9: =O9*12 -> 600 | S9: =P9*12 -> 780 | T9: =Q9*12 -> 1020 | U9: 40%-60%
A10: 7 | B10: 121 | C10: 92 | D10: 69 | E10: 65 | F10: 60 | G10: 49 | K10: TOTAL: | L10: =SUM(L4:L9) -> 2152800 | M10: =SUM(M4:M9) -> 3028800 | N10: =SUM(N4:N9) -> 4521600 | R10: =SUM(R4:R9) -> 5100 | S10: =SUM(S4:S9) -> 6900 | T10: =SUM(T4:T9) -> 9900
A11: 8 | B11: 104 | C11: 73 | D11: 64 | E11: 57 | F11: 52 | G11: 48
A12: 9 | B12: 103 | C12: 72 | D12: 59 | E12: 63 | F12: 51 | G12: 51 | L12: Costes de compra x unidades vendidas (€) | O12: Coste de reparación x unidades vendidas (€)
A13: 10 | B13: 106 | C13: 95 | D13: 68 | E13: 64 | F13: 54 | G13: 55 | K13: PRODUCTO | L13: AÑO 1 | M13: AÑO 2 | N13: AÑO 3 | O13: AÑO 1 | P13: AÑO 2 | Q13: AÑO 3
A14: 11 | B14: 126 | C14: 95 | D14: 81 | E14: 79 | F14: 61 | G14: 58 | K14: Móviles | L14: =R24*R4 -> 327600 | M14: =R24*S4 -> 499200 | N14: =R24*T4 -> 826800 | O14: =S24*R4 -> 107100 | P14: =S24*S4 -> 163200 | Q14: =S24*T4 -> 270300
A15: 12 | B15: 130 | C15: 106 | D15: 83 | E15: 81 | F15: 66 | G15: 60 | K15: Auriculares | L15: =R25*R5 -> 122400 | M15: =R25*S5 -> 144000 | N15: =R25*T5 -> 187200 | O15: =S25*R5 -> 40800 | P15: =S25*S5 -> 48000 | Q15: =S25*T5 -> 62400
A16: Media: | B16: =AVERAGE(B4:B15) -> 105 | C16: =AVERAGE(C4:C15) -> 85 | D16: =AVERAGE(D4:D15) -> 65 | E16: =AVERAGE(E4:E15) -> 65 | F16: =AVERAGE(F4:F15) -> 55 | G16: =AVERAGE(G4:G15) -> 50 | K16: Ordenadores | L16: =R26*R6 -> 304200 | M16: =R26*S6 -> 444600 | N16: =R26*T6 -> 655200 | O16: =S26*R6 -> 140400 | P16: =S26*S6 -> 205200 | Q16: =S26*T6 -> 302400
A17: Total | B17: =SUM(B4:B15) -> 1260 | C17: =SUM(C4:C15) -> 1020 | D17: =SUM(D4:D15) -> 780 | E17: =SUM(E4:E15) -> 780 | F17: =SUM(F4:F15) -> 660 | G17: =SUM(G4:G15) -> 600 | K17: Altavoces | L17: =R27*R7 -> 58500 | M17: =R27*S7 -> 76500 | N17: =R27*T7 -> 94500 | O17: =S27*R7 -> 35100 | P17: =S27*S7 -> 45900 | Q17: =S27*T7 -> 56700
K18: Tabletas | L18: =R28*R8 -> 69300 | M18: =R28*S8 -> 88200 | N18: =R28*T8 -> 126000 | O18: =S28*R8 -> 56100 | P18: =S28*S8 -> 71400 | Q18: =S28*T8 -> 102000
B19: AÑO 0 | D19: AÑO 1 | F19: AÑO 2 | H19: AÑO 3 | K19: Relojes | L19: =R29*R9 -> 72000 | M19: =R29*S9 -> 93600 | N19: =R29*T9 -> 122400 | O19: =S29*R9 -> 33000 | P19: =S29*S9 -> 42900 | Q19: =S29*T9 -> 56100
A20: GASTO TALLERES | B20: =B39 -> 561000 | K20: TOTAL: | L20: =SUM(L14:L19) -> 954000 | M20: =SUM(M14:M19) -> 1346100 | N20: =SUM(N14:N19) -> 2012100 | O20: =SUM(O14:O19) -> 412500 | P20: =SUM(P14:P19) -> 576600 | Q20: =SUM(Q14:Q19) -> 849900
A21: GASTO ALQUILER | B21: 0 | D21: =(D38+F38)*12 -> 50700 | F21: =(D38+F38)*12 -> 50700 | H21: =(D38+F38)*12 -> 50700
A22: GASTO SUELDOS | B22: 0 | D22: 672000 | F22: 672000 | H22: 672000 | L22: Ganancias x unidades vendidas (€) | Q22: (por producto, de media)
A23: DEVOLUCIÓN PRESTAMO | B23: 0 | D23: =SUM(PRESTAMO!B9:B20) -> 107715.91 | F23: =SUM(PRESTAMO!B21:B32) -> 107715.91 | H23: =SUM(PRESTAMO!B33:B44) -> 107715.91 | K23: PRODUCTO | L23: AÑO 1 | M23: AÑO 2 | N23: AÑO 3 | P23: PRODUCTO | Q23: Ganancias (€) | R23: Coste (€) | S23: Coste reparación (€) | T23: Precio de venta (€)
A24: GASTO MAQUINARIA | B24: 18000 | K24: Móviles | L24: =R4*Q24 -> 321300 | M24: =S4*Q24 -> 489600 | N24: =T4*Q24 -> 810900 | P24: Móviles | Q24: =T24-R24-S24 -> 255 | R24: 260 | S24: 85 | T24: 600
A25: GASTO MOBILIARIO | B25: 32000 | K25: Auriculares | L25: =R5*Q25 -> 107100 | M25: =S5*Q25 -> 126000 | N25: =T5*Q25 -> 163800 | P25: Auriculares | Q25: =T25-R25-S25 -> 105 | R25: 120 | S25: 40 | T25: 265
A26: GASTOS DE COMPRA | B26: 0 | D26: =L20 -> 954000 | F26: =M20 -> 1346100 | H26: =N20 -> 2012100 | K26: Ordenadores | L26: =R6*Q26 -> 163800 | M26: =S6*Q26 -> 239400 | N26: =T6*Q26 -> 352800 | P26: Ordenadores | Q26: =T26-R26-S26 -> 210 | R26: 390 | S26: 180 | T26: 780
A27: GASTOS INTERES | B27: 0 | D27: =PRESTAMO!I14 -> 12553.391 | F27: =SUM(PRESTAMO!C21:C32) -> 7795.2135 | H27: =SUM(PRESTAMO!C33:C44) -> 2799.1249 | K27: Altavoces | L27: =R7*Q27 -> 62400 | M27: =S7*Q27 -> 81600 | N27: =T7*Q27 -> 100800 | P27: Altavoces | Q27: =T27-R27-S27 -> 80 | R27: 75 | S27: 45 | T27: 200
A28: GASTO DE REPARACIÓN | B28: 0 | D28: =O20 -> 412500 | F28: =P20 -> 576600 | H28: =Q20 -> 849900 | K28: Tabletas | L28: =R8*Q28 -> 62700 | M28: =S8*Q28 -> 79800 | N28: =T8*Q28 -> 114000 | P28: Tabletas | Q28: =T28-R28-S28 -> 95 | R28: 105 | S28: 85 | T28: 285
A29: GASTO MANTENIMIENTO | K29: Relojes | L29: =R9*Q29 -> 69000 | M29: =S9*Q29 -> 89700 | N29: =T9*Q29 -> 117300 | P29: Relojes | Q29: =T29-R29-S29 -> 115 | R29: 120 | S29: 55 | T29: 290
A30: - Luz, agua y gas | B30: 0 | D30: =D46*8*12 -> 43200 | F30: =D46*8*12 -> 43200 | H30: =D46*8*12 -> 43200 | K30: TOTAL: | L30: =SUM(L24:L29) -> 786300 | M30: =SUM(M24:M29) -> 1106100 | N30: =SUM(N24:N29) -> 1659600
A31: GASTO DE AMORTIZACIÓN | B31: 0 | D31: =D47*12*8 -> 43860 | F31: =D47*12*8 -> 43860 | H31: =D47*12*8 -> 43860
A32: MANTENIMIENTO PAGINA WEB | B32: 0 | D32: 4.45 | F32: 6.5 | H32: 6.5 | L32: SIN LOS 800000€ DE BASE
A33: COMPRA PÁGINA WEB | B33: 4.45 | L33: AÑO 1 | M33: AÑO 2 | N33: AÑO 3
A34: TOTAL | B34: =SUM(B20:B33) -> 611004.45 | D34: =SUM(D20:D32) -> 2296533.8 | F34: =SUM(F20:F33) -> 2847977.6 | H34: =SUM(H20:H32) -> 3782281.5 | K34: Ingresos | L34: =L10 -> 2152800 | M34: =M10 -> 3028800 | N34: =N10 -> 4521600
K35: Gastos totales (€) | L35: =D34+B34 -> 2907538.2 | M35: =F34 -> 2847977.6 | N35: =H34 -> 3782281.5
A36: TALLERES (compra) | D36: LOCALES (alquiler total/mes) | K36: Profit (€) | L36: =L34-L35 -> -754738.2 | M36: =M34-M35 -> 180822.38 | N36: =N34-N35 -> 739318.47
A37: Madrid (1) | B37: Barcelona (1) | D37: Madrid (3) | F37: Barcelona (3) | K37: Profit a los 3 años (€) | L37: =L36+M36+N36 -> 165402.64
A38: 361000 | B38: 200000 | D38: 2125 | F38: 2100
A39: TOTAL : | B39: =SUM(A38:C38) -> 561000 | D39: TOTAL mensual : | F39: =SUM(D38:G38) -> 4225
D40: TOTAL anual : | F40: =F39*12 -> 50700
K41: Precio de venta x unidades vendidas (€) / MES (AÑO1)
...

Sheet TESORERIA
D2: MESES (AÑO 1)
B3: FLUJO DE CAJA | C3: APERTURA | D3: 1 | E3: 2 | F3: 3 | G3: 4 | H3: 5 | I3: 6 | J3: 7 | K3: 8 | L3: 9 | M3: 10 | N3: 11 | O3: 12 | P3: AÑO 2 | Q3: AÑO 3
B4: INGRESOS (€)
B5: VENTAS (€) | C5: 0 | D5: ='VENTA Y GASTO'!K43 -> 144465 | E5: ='VENTA Y GASTO'!L43 -> 151630 | F5: ='VENTA Y GASTO'!M43 -> 158675 | G5: ='VENTA Y GASTO'!N43 -> 164945 | H5: ='VENTA Y GASTO'!O43 -> 169405 | I5: ='VENTA Y GASTO'!P43 -> 204785 | J5: ='VENTA Y GASTO'!Q43 -> 195110 | K5: ='VENTA Y GASTO'!R43 -> 171805 | ... O5: ='VENTA Y GASTO'!V43 -> 223240 | P5: ='VENTA Y GASTO'!M10 -> 3028800 | Q5: ='VENTA Y GASTO'!N10 -> 4521600
B6: APORTE (€) | C6: =500000 -> 500000
B7: PRESTAMOS (€) | C7: 300000
B8: TOTAL INGRESO | C8: =SUM(C5:C7) -> 800000 | D8: =D5+D6+D7 -> 144465 | E8: =E5+E6+E7 -> 151630 | F8: =F5+F6+F7 -> 158675 | G8: =G5+G6+G7 -> 164945 | H8: =H5+H6+H7 -> 169405 | I8: =I5+I6+I7 -> 204785 | J8: =J5+J6+J7 -> 195110 | K8: =K5+K6+K7 -> 171805 | ... O8: =O5+O6+O7 -> 223240 | P8: =P5+P7 -> 3028800 | Q8: =Q5+Q7 -> 4521600
B9: GASTOS (€)
B10: TALLERES (€) | C10: ='VENTA Y GASTO'!B39 -> 561000
B11: ALQUILER (€) | C11: 0 | D11: ='VENTA Y GASTO'!F39 -> 4225 | E11: ='VENTA Y GASTO'!F39 -> 4225 | F11: ='VENTA Y GASTO'!F39 -> 4225 | G11: ='VENTA Y GASTO'!F39 -> 4225 | H11: ='VENTA Y GASTO'!F39 -> 4225 | I11: ='VENTA Y GASTO'!F39 -> 4225 | J11: ='VENTA Y GASTO'!F39 -> 4225 | K11: ='VENTA Y GASTO'!F39 -> 4225 | L11: ='VENTA Y GASTO'!F39 -> 4225 | M11: ='VENTA Y GASTO'!F39 -> 4225 | N11: ='VENTA Y GASTO'!F39 -> 4225 | O11: ='VENTA Y GASTO'!F39 -> 4225 | P11: ='VENTA Y GASTO'!F40 -> 50700 | Q11: ='VENTA Y GASTO'!F40 -> 50700
B12: SUELDOS (€) | C12: 0 | D12: ='VENTA Y GASTO'!D58 -> 56000 | E12: ='VENTA Y GASTO'!D58 -> 56000 | F12: ='VENTA Y GASTO'!D58 -> 56000 | G12: ='VENTA Y GASTO'!D58 -> 56000 | H12: ='VENTA Y GASTO'!D58 -> 56000 | I12: ='VENTA Y GASTO'!D58 -> 56000 | J12: ='VENTA Y GASTO'!D58 -> 56000 | K12: ='VENTA Y GASTO'!D58 -> 56000 | L12: ='VENTA Y GASTO'!D58 -> 56000 | M12: ='VENTA Y GASTO'!D58 -> 56000 | N12: ='VENTA Y GASTO'!D58 -> 56000 | O12: ='VENTA Y GASTO'!D58 -> 56000 | P12: ='VENTA Y GASTO'!E58 -> 672000 | Q12: ='VENTA Y GASTO'!E58 -> 672000
B13: MAQUINARIA (€) | C13: ='VENTA Y GASTO'!B24 -> 18000
B14: MOBILIARIO (€) | C14: ='VENTA Y GASTO'!B25 -> 32000
B15: MANTENIMIENTO (€)
B16: - Luz, agua y gas | C16: 0 | D16: ='VENTA Y GASTO'!D46*8 -> 3600 | E16: ='VENTA Y GASTO'!D46*8 -> 3600 | F16: ='VENTA Y GASTO'!D46*8 -> 3600 | G16: ='VENTA Y GASTO'!D46*8 -> 3600 | H16: ='VENTA Y GASTO'!D46*8 -> 3600 | I16: ='VENTA Y GASTO'!D46*8 -> 3600 | J16: ='VENTA Y GASTO'!D46*8 -> 3600 | K16: ='VENTA Y GASTO'!D46*8 -> 3600 | L16: ='VENTA Y GASTO'!D46*8 -> 3600 | M16: ='VENTA Y GASTO'!D46*8 -> 3600 | N16: ='VENTA Y GASTO'!D46*8 -> 3600 | O16: ='VENTA Y GASTO'!D46*8 -> 3600 | P16: ='VENTA Y GASTO'!D46*8*12 -> 43200 | Q16: ='VENTA Y GASTO'!D46*8*12 -> 43200
B17: REACONDICIONAMIENTO (€) | C17: 0 | D17: ='VENTA Y GASTO'!K47 -> 27480 | E17: ='VENTA Y GASTO'!L47 -> 28970 | F17: ='VENTA Y GASTO'!M47 -> 30590 | G17: ='VENTA Y GASTO'!N47 -> 31795 | H17: ='VENTA Y GASTO'!O47 -> 32890 | I17: ='VENTA Y GASTO'!P47 -> 39185 | J17: ='VENTA Y GASTO'!Q47 -> 37105 | K17: ='VENTA Y GASTO'!R47 -> 32905 | ... O17: ='VENTA Y GASTO'!V47 -> 42785 | P17: ='VENTA Y GASTO'!P20 -> 576600 | Q17: ='VENTA Y GASTO'!Q20 -> 849900
B18: INTERESES (€) | C18: 0 | D18: =PRESTAMO!C9 -> 1222.25 | E18: =PRESTAMO!C10 -> 1190.6586 | F18: =PRESTAMO!C11 -> 1158.9385 | G18: =PRESTAMO!C12 -> 1127.0892 | H18: =PRESTAMO!C13 -> 1095.1101 | I18: =PRESTAMO!C14 -> 1063.0007 | J18: =PRESTAMO!C15 -> 1030.7605 | K18: =PRESTAMO!C16 -> 998.38891 | L18: =PRESTAMO!C17 -> 965.88547 | M18: =PRESTAMO!C18 -> 933.2496 | N18: =PRESTAMO!C19 -> 900.48076 | O18: =PRESTAMO!C20 -> 867.57843 | P18: =SUM(PRESTAMO!C21:C32) -> 7795.2135 | Q18: =SUM(PRESTAMO!C33:C44) -> 2799.1249
B19: DEVOLUCION DEL PRESTAMO (€) | C19: 0 | D19: =PRESTAMO!D9 -> 7754.0758 | E19: =PRESTAMO!D10 -> 7785.6672 | F19: =PRESTAMO!D11 -> 7817.3873 | G19: =PRESTAMO!D12 -> 7849.2366 | H19: =PRESTAMO!D13 -> 7881.2157 | I19: =PRESTAMO!D14 -> 7913.3251 | J19: =PRESTAMO!D15 -> 7945.5653 | K19: =PRESTAMO!D16 -> 7977.9369 | L19: =PRESTAMO!D17 -> 8010.4403 | M19: =PRESTAMO!D18 -> 8043.0762 | N19: =PRESTAMO!D19 -> 8075.845 | O19: =PRESTAMO!D20 -> 8108.7474 | P19: =PRESTAMO!I27 -> 99920.696 | Q19: =PRESTAMO!I39 -> 104916.78
B20: DE COMPRA (€) | C20: 0 | D20: ='VENTA Y GASTO'!K51 -> 64025 | E20: ='VENTA Y GASTO'!L51 -> 67175 | F20: ='VENTA Y GASTO'!M51 -> 70205 | G20: ='VENTA Y GASTO'!N51 -> 73000 | H20: ='VENTA Y GASTO'!O51 -> 74825 | I20: ='VENTA Y GASTO'!P51 -> 90735 | J20: ='VENTA Y GASTO'!Q51 -> 86465 | K20: ='VENTA Y GASTO'!R51 -> 76255 | ... O20: ='VENTA Y GASTO'!V51 -> 99095 | P20: ='VENTA Y GASTO'!M20 -> 1346100 | Q20: ='VENTA Y GASTO'!N20 -> 2012100
B21: IMPUESTO DE SOCIEDADES | C21: 0 | D21: 0 | E21: 0 | F21: 0 | G21: 0 | H21: 0 | I21: 0 | J21: 0 | K21: 0 | L21: 0 | M21: 0 | N21: 0 | O21: 0 | P21: ='CUENTA DE PYG'!L20 -> 72134.572 | Q21: ='CUENTA DE PYG'!D44 -> 211758.59
B22: COMPRA PÁGINA WEB | C22: 4.45 | D22: 0 | E22: 0 | F22: 0 | G22: 0 | H22: 0 | I22: 0 | J22: 0 | K22: 0 | L22: 0 | M22: 0 | N22: 0 | O22: 0 | P22: 0 | Q22: 0
B23: MANTENIMIENTO PÁGINA WEB | C23: 0 | D23: 4.45 | E23: 0 | F23: 0 | G23: 0 | H23: 0 | I23: 0 | J23: 0 | K23: 0 | L23: 0 | M23: 0 | N23: 0 | O23: 0 | P23: ='VENTA Y GASTO'!F32 -> 6.5 | Q23: ='VENTA Y GASTO'!H32 -> 6.5
B24: TOTAL EGRESO | C24: =SUM(C10:C23) -> 611004.45 | D24: =SUM(D10:D23) -> 164310.78 | E24: =SUM(E10:E23) -> 168946.33 | F24: =SUM(F10:F23) -> 173596.33 | G24: =SUM(G10:G23) -> 177596.33 | H24: =SUM(H10:H23) -> 180516.33 | I24: =SUM(I10:I23) -> 202721.33 | J24: =SUM(J10:J23) -> 196371.33 | ... Q24: =SUM(Q10:Q23) -> 3947381
B25: TOTAL MES (AÑO 1) | C25: =C8-C24 -> 188995.55 | D25: =D8-D24 -> -19845.776 | E25: =E8-E24 -> -17316.326 | F25: =F8-F24 -> -14921.326 | G25: =G8-G24 -> -12651.326 | H25: =H8-H24 -> -11111.326 | I25: =I8-I24 -> 2063.6742 | J25: =J8-J24 -> -1261.3258 | ... O25: =O8-O24 -> 8558.6742
B26: TOTAL ANUAL | C26: =SUM(C25:O25) -> 101675.19 | P26: =P8-P24 -> 160343.02 | Q26: =Q8-Q24 -> 574219
B27: TESORERÍA | C27: =C25 -> 188995.55 | D27: =C27+D25 -> 169149.77 | E27: =D27+E25 -> 151833.45 | F27: =E27+F25 -> 136912.12 | G27: =F27+G25 -> 124260.8 | H27: =G27+H25 -> 113149.47 | I27: =H27+I25 -> 115213.15 | J27: =I27+J25 -> 113951.82 | K27: =J27+K25 -> 103795.49 | ... O27: =N27+O25 -> 101675.19 | P27: =O27+P26 -> 262018.21 | Q27: =P27+Q26 -> 836237.21
K30: 101675.19
C31: Los gastos totales de forma anual se caracterizan por ser | I31: =SUM(C24:O24) -> 2851124.8 | K31: 160343.02
I32: =SUM(C8:O8) -> 2952800
O33: 574219

Sheet PRESTAMO
A1: CAPITAL | B1: 300000 | D1: Plan de amortización | F1: Conversor de TAE a TIN
A2: AÑOS | B2: 3 | D2: Método Francés | F2: TAE | G2: 0.05
A3: PAGOS ANUALES | B3: 12 | C3: =PRESTAMO!B3*PRESTAMO!B2 -> 36 | D3: CUOTA DEL PERIODO | F3: Periodos al año | G3: 12
A4: TIPO DE INTERÉS NOMINAL | B4: 0.04889 | C4: =B4/B3 -> 0.0040741667 | D4: =-(B1*-1)/((((1+C4)^C3)-1)/(((1+C4)^C3)*C4)) -> 8976.3258 | F4: Interés nominal | G4: =NOMINAL(G2,G3) -> 0.048889485
A7: Mes | B7: Cuota | C7: Interés | D7: Capital amortizado | E7: Capital pendiente
A8: 0 | E8: =PRESTAMO!B1 -> 300000
A9: =A8+1 -> 1 | B9: =D4 -> 8976.3258 | C9: =E8*$C$4 -> 1222.25 | D9: =B9-C9 -> 7754.0758 | E9: =E8-D9 -> 292245.92
A10: =A9+1 -> 2 | B10: =B9 -> 8976.3258 | C10: =E9*$C$4 -> 1190.6586 | D10: =B10-C10 -> 7785.6672 | E10: =E9-D10 -> 284460.26
A11: =A10+1 -> 3 | B11: =B10 -> 8976.3258 | C11: =E10*$C$4 -> 1158.9385 | D11: =B11-C11 -> 7817.3873 | E11: =E10-D11 -> 276642.87 | G11: deuda en balance de apertura
A12: =A11+1 -> 4 | B12: =B11 -> 8976.3258 | C12: =E11*$C$4 -> 1127.0892 | D12: =B12-C12 -> 7849.2366 | E12: =E11-D12 -> 268793.63 | G12: corto plazo | I12: =SUM(D9:D20) -> 95162.519
A13: =A12+1 -> 5 | B13: =B12 -> 8976.3258 | C13: =E12*$C$4 -> 1095.1101 | D13: =B13-C13 -> 7881.2157 | E13: =E12-D13 -> 260912.42 | G13: largo plazo | I13: =E8-I12 -> 204837.48
A14: =A13+1 -> 6 | B14: =B13 -> 8976.3258 | C14: =E13*$C$4 -> 1063.0007 | D14: =B14-C14 -> 7913.3251 | E14: =E13-D14 -> 252999.09 | G14: gastos de interes del año 1 : | I14: =SUM(C9:C20) -> 12553.391
A15: =A14+1 -> 7 | B15: =B14 -> 8976.3258 | C15: =E14*$C$4 -> 1030.7605 | D15: =B15-C15 -> 7945.5653 | E15: =E14-D15 -> 245053.53 | G15: gastos de devolución del año 1 : | I15: =SUM(D9:D20) -> 95162.519
A16: =A15+1 -> 8 | B16: =B15 -> 8976.3258 | C16: =E15*$C$4 -> 998.38891 | D16: =B16-C16 -> 7977.9369 | E16: =E15-D16 -> 237075.59
A17: =A16+1 -> 9 | B17: =B16 -> 8976.3258 | C17: =E16*$C$4 -> 965.88547 | D17: =B17-C17 -> 8010.4403 | E17: =E16-D17 -> 229065.15 | G17: gasto financiero año 1
A18: =A17+1 -> 10 | B18: =B17 -> 8976.3258 | C18: =E17*$C$4 -> 933.2496 | D18: =B18-C18 -> 8043.0762 | E18: =E17-D18 -> 221022.07 | G18: intereses | I18: =SUM(C9:C20) -> 12553.391
A19: =A18+1 -> 11 | B19: =B18 -> 8976.3258 | C19: =E18*$C$4 -> 900.48076 | D19: =B19-C19 -> 8075.845 | E19: =E18-D19 -> 212946.23
A20: =A19+1 -> 12 | B20: =B19 -> 8976.3258 | C20: =E19*$C$4 -> 867.57843 | D20: =B20-C20 -> 8108.7474 | E20: =E19-D20 -> 204837.48 | F20: =E8-E20 -> 95162.519
A21: =A20+1 -> 13 | B21: =B20 -> 8976.3258 | C21: =E20*$C$4 -> 834.54204 | D21: =B21-C21 -> 8141.7838 | E21: =E20-D21 -> 196695.7
A22: =A21+1 -> 14 | B22: =B21 -> 8976.3258 | C22: =E21*$C$4 -> 801.37105 | D22: =B22-C22 -> 8174.9548 | E22: =E21-D22 -> 188520.74
A23: =A22+1 -> 15 | B23: =B22 -> 8976.3258 | C23: =E22*$C$4 -> 768.06492 | D23: =B23-C23 -> 8208.2609 | E23: =E22-D23 -> 180312.48 | G23: balance de final de año 1
A24: =A23+1 -> 16 | B24: =B23 -> 8976.3258 | C24: =E23*$C$4 -> 734.6231 | D24: =B24-C24 -> 8241.7027 | E24: =E23-D24 -> 172070.78 | G24: corto plazo | I24: =SUM(D21:D32) -> 99920.696
A25: =A24+1 -> 17 | B25: =B24 -> 8976.3258 | C25: =E24*$C$4 -> 701.04503 | D25: =B25-C25 -> 8275.2808 | E25: =E24-D25 -> 163795.5 | G25: largo plazo | I25: =E32 -> 104916.78
A26: =A25+1 -> 18 | B26: =B25 -> 8976.3258 | C26: =E25*$C$4 -> 667.33016 | D26: =B26-C26 -> 8308.9956 | E26: =E25-D26 -> 155486.5 | G26: gastos de interes del año 1 : | I26: =SUM(C21:C32) -> 7795.2135
A27: =A26+1 -> 19 | B27: =B26 -> 8976.3258 | C27: =E26*$C$4 -> 633.47793 | D27: =B27-C27 -> 8342.8479 | E27: =E26-D27 -> 147143.65 | G27: gastos de devolución del año 2 : | I27: =SUM(D21:D32) -> 99920.696
A28: =A27+1 -> 20 | B28: =B27 -> 8976.3258 | C28: =E27*$C$4 -> 599.48777 | D28: =B28-C28 -> 8376.838 | E28: =E27-D28 -> 138766.82
A29: =A28+1 -> 21 | B29: =B28 -> 8976.3258 | C29: =E28*$C$4 -> 565.35914 | D29: =B29-C29 -> 8410.9667 | E29: =E28-D29 -> 130355.85 | G29: gastos financieros de año 2
A30: =A29+1 -> 22 | B30: =B29 -> 8976.3258 | C30: =E29*$C$4 -> 531.09146 | D30: =B30-C30 -> 8445.2343 | E30: =E29-D30 -> 121910.62 | G30: intereses | I30: =SUM(C21:C32) -> 7795.2135
A31: =A30+1 -> 23 | B31: =B30 -> 8976.3258 | C31: =E30*$C$4 -> 496.68417 | D31: =B31-C31 -> 8479.6416 | E31: =E30-D31 -> 113430.97
A32: =A31+1 -> 24 | B32: =B31 -> 8976.3258 | C32: =E31*$C$4 -> 462.13669 | D32: =B32-C32 -> 8514.1891 | E32: =E31-D32 -> 104916.78
A33: =A32+1 -> 25 | B33: =B32 -> 8976.3258 | C33: =E32*$C$4 -> 427.44847 | D33: =B33-C33 -> 8548.8773 | E33: =E32-D33 -> 96367.907
A34: =A33+1 -> 26 | B34: =B33 -> 8976.3258 | C34: =E33*$C$4 -> 392.61892 | D34: =B34-C34 -> 8583.7069 | E34: =E33-D34 -> 87784.201
A35: =A34+1 -> 27 | B35: =B34 -> 8976.3258 | C35: =E34*$C$4 -> 357.64746 | D35: =B35-C35 -> 8618.6783 | E35: =E34-D35 -> 79165.522 | G35: balance de final de año 2
A36: =A35+1 -> 28 | B36: =B35 -> 8976.3258 | C36: =E35*$C$4 -> 322.53353 | D36: =B36-C36 -> 8653.7923 | E36: =E35-D36 -> 70511.73 | G36: corto plazo | I36: =SUM(D33:D44) -> 104916.78
A37: =A36+1 -> 29 | B37: =B36 -> 8976.3258 | C37: =E36*$C$4 -> 287.27654 | D37: =B37-C37 -> 8689.0493 | E37: =E36-D37 -> 61822.681 | G37: largo plazo | I37: 0
A38: =A37+1 -> 30 | B38: =B37 -> 8976.3258 | C38: =E37*$C$4 -> 251.8759 | D38: =B38-C38 -> 8724.4499 | E38: =E37-D38 -> 53098.231 | G38: gastos de interes del año 1 : | I38: =SUM(C33:C44) -> 2799.1249
A39: =A38+1 -> 31 | B39: =B38 -> 8976.3258 | C39: =E38*$C$4 -> 216.33104 | D39: =B39-C39 -> 8759.9948 | E39: =E38-D39 -> 44338.236 | G39: gastos de devolución del año 3 : | I39: =SUM(D33:D44) -> 104916.78
A40: =A39+1 -> 32 | B40: =B39 -> 8976.3258 | C40: =E39*$C$4 -> 180.64136 | D40: =B40-C40 -> 8795.6844 | E40: =E39-D40 -> 35542.552
A41: =A40+1 -> 33 | B41: =B40 -> 8976.3258 | C41: =E40*$C$4 -> 144.80628 | D41: =B41-C41 -> 8831.5195 | E41: =E40-D41 -> 26711.032 | G41: gastos financieros de año 3
A42: =A41+1 -> 34 | B42: =B41 -> 8976.3258 | C42: =E41*$C$4 -> 108.8252 | D42: =B42-C42 -> 8867.5006 | E42: =E41-D42 -> 17843.531 | G42: intereses | I42: =SUM(C33:C44) -> 2799.1249
...

Sheet CUENTA DE PYG
B2: CUENTA DE RESULTADOS AÑO1 | J2: CUENTA DE RESULTADOS AÑO2
B3: Ingresos de explotación | F3: =D4 -> 2152800 | J3: Ingresos de explotación | N3: =L4 -> 3028800
B4: Venta de mercaderias | D4: =SUM(TESORERIA!D5:O5) -> 2152800 | J4: Venta de mercaderias | L4: =TESORERIA!P5 -> 3028800
B5: Gastos de explotación | F5: =SUM(D6:E12) -> 2176264.5 | J5: Gastos de explotación | N5: =SUM(L6:M12) -> 2732466.5
B6: Compra de mercaderia | D6: =SUM(TESORERIA!D20:O20) -> 954000 | J6: Compra de mercaderia | L6: =TESORERIA!P20 -> 1346100
B7: Alquiler de tiendas | D7: =SUM(TESORERIA!D11:O11) -> 50700 | J7: Alquiler de tiendas | L7: =TESORERIA!P11 -> 50700
B8: Costes de reparacion | D8: =SUM(TESORERIA!D17:O17) -> 412500 | J8: Costes de reparacion | L8: =TESORERIA!P17 -> 576600
B9: Sueldos y salarios | D9: =SUM(TESORERIA!D12:O12) -> 672000 | J9: Sueldos y salarios | L9: =TESORERIA!P12 -> 672000
B10: Suministro de luz,agua y gas | D10: =SUM(TESORERIA!D16:O16) -> 43200 | J10: Suministro de luz,agua y gas | L10: =TESORERIA!P16 -> 43200
B11: Amortización Inm. material | D11: ='VENTA Y GASTO'!D31 -> 43860 | J11: Amortización Inm. material | L11: ='VENTA Y GASTO'!D31 -> 43860
B12: Página web | D12: ='VENTA Y GASTO'!D32 -> 4.45 | J12: Pagina web | L12: ='VENTA Y GASTO'!F32 -> 6.5
B13: Resultados de explotacion | F13: =D4-F5 -> -23464.45 | J13: Resultados de explotacion | N13: =N3-N5 -> 296333.5
B14: Ingesos financieros | F14: =D15 -> 0 | J14: Ingesos financieros | N14: =L15 -> 0
D15: 0 | L15: 0
B16: Gastos financieros | F16: =D17 -> 12553.391 | J16: Gastos financieros | N16: =L17 -> 7795.2135
B17: Intereses de préstamo | D17: =PRESTAMO!I18 -> 12553.391 | J17: Intereses de préstamo | L17: =PRESTAMO!I30 -> 7795.2135
B18: Resusltado financiero | F18: =F14-F16 -> -12553.391 | J18: Resusltado financiero | N18: =N14-N16 -> -7795.2135
B19: Resultado antes de impuestos | F19: =F13+F18 -> -36017.841 | J19: Resultado antes de impuestos | N19: =N13+N18 -> 288538.29
B20: Impuestos sobre beneficios (25%) | D20: 0 | J20: Impuestos sobre beneficios (25%) | L20: =N19*0.25 -> 72134.572
B21: Resultado del ejercicio | F21: =F19 -> -36017.841 | J21: Resultado del ejercicio | N21: =N19-L20 -> 216403.71
B26: CUENTA DE RESULTADOS AÑO3 | J26: SIMPLIFICACIÓN VISUAL PARA LOS 3 AÑOS | L26: AÑO 1 | N26: AÑO 2 | P26: AÑO 3
B27: Ingresos de explotación | F27: =D28 -> 4521600 | J27: Ingresos de explotación | M27: =F3 -> 2152800 | O27: =N3 -> 3028800 | Q27: =F27 -> 4521600
B28: Venta de mercaderias | D28: =TESORERIA!Q5 -> 4521600 | J28: Venta de mercaderias | L28: =D4 -> 2152800 | N28: =L4 -> 3028800 | P28: =D28 -> 4521600 | Q28: =F28 -> 0
B29: Gastos de explotación | F29: =SUM(D30:E36) -> 3671766.5 | J29: Gastos de explotación | M29: =F5 -> 2176264.5 | N29: =L5 -> 0 | O29: =N5 -> 2732466.5 | P29: =D29 -> 0 | Q29: =F29 -> 3671766.5
B30: Compra de mercaderia | D30: =TESORERIA!Q20 -> 2012100 | J30: Compra de mercaderia | L30: =D6 -> 954000 | N30: =L6 -> 1346100 | P30: =D30 -> 2012100 | Q30: =F30 -> 0
B31: Alquiler de tiendas | D31: =TESORERIA!P11 -> 50700 | J31: Alquiler de tiendas | L31: =D7 -> 50700 | N31: =L7 -> 50700 | P31: =D31 -> 50700 | Q31: =F31 -> 0
B32: Costes de reparacion | D32: =TESORERIA!Q17 -> 849900 | J32: Costes de reparacion | L32: =D8 -> 412500 | N32: =L8 -> 576600 | P32: =D32 -> 849900 | Q32: =F32 -> 0
B33: Sueldos y salarios | D33: =TESORERIA!Q12 -> 672000 | J33: Sueldos y salarios | L33: =D9 -> 672000 | N33: =L9 -> 672000 | P33: =D33 -> 672000 | Q33: =F33 -> 0
B34: Suministro de luz,agua y gas | D34: =TESORERIA!Q16 -> 43200 | J34: Suministro de luz,agua y gas | L34: =D10 -> 43200 | N34: =L10 -> 43200 | P34: =D34 -> 43200 | Q34: =F34 -> 0
B35: Amortización Inm. material | D35: ='VENTA Y GASTO'!D31 -> 43860 | J35: Amortización Inm. material | L35: =D11 -> 43860 | N35: =L11 -> 43860 | P35: =D35 -> 43860 | Q35: =F35 -> 0
B36: Página web | D36: ='VENTA Y GASTO'!H32 -> 6.5 | J36: Página web | L36: =D12 -> 4.45 | N36: =L12 -> 6.5 | P36: =D36 -> 6.5 | Q36: =F36 -> 0
B37: Resultados de explotacion | F37: =F27-F29 -> 849833.5 | J37: Resultados de explotacion | M37: =F13 -> -23464.45 | N37: =L13 -> 0 | O37: =N13 -> 296333.5 | P37: =D37 -> 0 | Q37: =F37 -> 849833.5
B38: Ingesos financieros | F38: =D39 -> 0 | J38: Ingesos financieros | M38: 0 | N38: =L14 -> 0 | O38: =N14 -> 0 | P38: =D38 -> 0 | Q38: =F38 -> 0
D39: 0 | L39: 0 | N39: =L15 -> 0 | P39: =D39 -> 0 | Q39: =F39 -> 0
B40: Gastos financieros | F40: =D41 -> 2799.1249 | J40: Gastos financieros | M40: =F16 -> 12553.391 | N40: =L16 -> 0 | O40: =N16 -> 7795.2135 | P40: =D40 -> 0 | Q40: =F40 -> 2799.1249
B41: Intereses de préstamo | D41: =PRESTAMO!I42 -> 2799.1249 | J41: Intereses de préstamo | L41: =D17 -> 12553.391 | N41: =L17 -> 7795.2135 | P41: =D41 -> 2799.1249 | Q41: =F41 -> 0
B42: Resusltado financiero | F42: =F38-F40 -> -2799.1249 | J42: Resusltado financiero | M42: =F18 -> -12553.391 | N42: =L18 -> 0 | O42: =N18 -> -7795.2135 | P42: =D42 -> 0 | Q42: =F42 -> -2799.1249
B43: Resultado antes de impuestos | F43: =F37+F42 -> 847034.38 | J43: Resultado antes de impuestos | M43: =F19 -> -36017.841 | N43: =L19 -> 0 | O43: =N19 -> 288538.29 | P43: =D43 -> 0 | Q43: =F43 -> 847034.38
B44: Impuestos sobre beneficios (25%) | D44: =F43*0.25 -> 211758.59 | J44: Impuestos sobre beneficios, 25% | L44: =D20 -> 0 | N44: =L20 -> 72134.572 | P44: =D44 -> 211758.59 | Q44: =F44 -> 0
B45: Resultado del ejercicio | F45: =F43-D44 -> 635275.78 | J45: Resultado del ejercicio | M45: =F21 -> -36017.841 | O45: =N21 -> 216403.71 | Q45: =F45 -> 635275.78

Sheet BALANCES
B2: BALANCE DE APERTURA | J2: BALANCE AÑO 1
B3: Activo | E3: Patrimonio neto y pasivo | J3: Activo | M3: Patrimonio neto y pasivo
B4: No corriente | C4: =C6+C7+C8+C9+C5 -> 611004.45 | E4: Patrimonio neto | F4: =F5+F6+F7 -> 500000 | J4: No corriente | K4: =K6+K7+K8+K9+K5 -> 567144.45 | M4: Patrimonio neto | N4: =N5+N6+N7 -> 463982.16
B5: Página web | C5: =TESORERIA!C22 -> 4.45 | E5: Capital Social | F5: 500000 | J5: Página web | K5: ='VENTA Y GASTO'!D32 -> 4.45 | M5: Capital Social | N5: 500000 | Q5: RESUMEN DE LOS 3 AÑOS
B6: Talleres | C6: =TESORERIA!C10 -> 561000 | E6: Res. ejs. anteriores | F6: 0 | J6: Talleres | K6: =TESORERIA!C10 -> 561000 | M6: Res. ejs. anteriores | N6: 0
B7: Maquinaria | C7: =TESORERIA!C13 -> 18000 | E7: Pérdidas y ganancias | F7: 0 | J7: Maquinaria | K7: =TESORERIA!C13 -> 18000 | M7: Pérdidas y ganancias | N7: ='CUENTA DE PYG'!F21 -> -36017.841 | R7: AÑO 1 | S7: AÑO 2 | T7: AÑO 3
B8: Mobiliario | C8: =TESORERIA!C14 -> 32000 | E8: Pasivo | F8: =F9+F11 -> 300000 | J8: Mobiliario | K8: =TESORERIA!C14 -> 32000 | M8: Pasivo | N8: =N10+N11 -> 204837.48 | Q8: Activo
B9: Amortización acum. | C9: 0 | E9: Largo Plazo | F9: =F10 -> 204837.48 | J9: Amortización acum. | K9: =-'CUENTA DE PYG'!D11 -> -43860 | M9: Largo Plazo | N9: =N10 -> 104916.78 | Q9: No corriente | R9: 567144.45 | S9: 523284.45 | T9: 479424.45
B10: Corriente | C10: =C11+C12+C13 -> 188995.55 | E10: Capital pendiente | F10: =PRESTAMO!I13 -> 204837.48 | J10: Corriente | K10: =K11+K12+K13+K14 -> 101675.19 | M10: Capital pendiente | N10: =PRESTAMO!I25 -> 104916.78 | Q10: Página web | R10: 4.45 | S10: 4.45 | T10: 4.45
B11: Existente | C11: 0 | E11: Corto Plazo | F11: =F12 -> 95162.519 | J11: Existente | K11: 0 | M11: Corto Plazo | N11: =PRESTAMO!I24 -> 99920.696 | Q11: Talleres | R11: 561000 | S11: 561000 | T11: 561000
B12: Realizable | C12: 0 | E12: Capital pendiente | F12: =PRESTAMO!I12 -> 95162.519 | J12: Realizable | K12: 0 | M12: Capital pendiente | N12: =PRESTAMO!I24 -> 99920.696 | Q12: Maquinaria | R12: 18000 | S12: 18000 | T12: 18000
B13: Disponible | C13: =TESORERIA!C27 -> 188995.55 | J13: Disponible | K13: =TESORERIA!O27 -> 101675.19 | Q13: Mobiliario | R13: 32000 | S13: 32000 | T13: 32000
Q14: Amortización acum. | R14: -43860 | S14: -87720 | T14: -131580
B15: TOTAL | C15: =C4+C10 -> 800000 | E15: TOTAL | F15: =F8+F4 -> 800000 | J15: TOTAL | K15: =K4+K10 -> 668819.64 | M15: TOTAL | N15: =N8+N4 -> 668819.64 | Q15: Corriente | R15: 101675.19 | S15: 262018.21 | T15: 836237.21
Q16: Existente | R16: 0 | S16: 0 | T16: 0
Q17: Realizable | R17: 0 | S17: 0 | T17: 0
Q18: Disponible | R18: 101675.19 | S18: 262018.21 | T18: 836237.21
Q20: TOTAL | R20: 668819.64 | S20: 785302.66 | T20: 1315661.7
B21: BALANCE AÑO 2 | J21: BALANCE AÑO 3 | Z21: .
B22: Activo | E22: Patrimonio neto y pasivo | J22: Activo | M22: Patrimonio neto y pasivo | Q22: Patrimonio neto y pasivo
B23: No corriente | C23: =C25+C26+C27+C28+C24 -> 523284.45 | E23: Patrimonio neto | F23: =F24+F25+F26 -> 680385.87 | J23: No corriente | K23: =K25+K26+K27+K28+K24 -> 479424.45 | M23: Patrimonio neto | N23: =N24+N25+N26 -> 1315661.7 | Q23: Patrimonio neto | R23: 463982.16 | S23: 680385.87 | T23: 1315661.7
B24: Pagina web | C24: 4.45 | E24: Capital Social | F24: 500000 | J24: Página web | K24: 4.45 | M24: Capital Social | N24: 500000 | Q24: Capital Social | R24: 500000 | S24: 500000 | T24: 500000
B25: Talleres | C25: =TESORERIA!C10 -> 561000 | E25: Res. ejs. anteriores | F25: ='CUENTA DE PYG'!F21 -> -36017.841 | J25: Talleres | K25: =TESORERIA!C10 -> 561000 | M25: Res. ejs. anteriores | N25: =F26+F25 -> 180385.87 | Q25: Res. ejs. anteriores | R25: 0 | S25: -36017.841 | T25: 180385.87
B26: Maquinaria | C26: =TESORERIA!C13 -> 18000 | E26: Pérdidas y ganancias | F26: ='CUENTA DE PYG'!N21 -> 216403.71 | J26: Maquinaria | K26: =TESORERIA!C13 -> 18000 | M26: Pérdidas y ganancias | N26: ='CUENTA DE PYG'!F45 -> 635275.78 | Q26: Pérdidas y ganancias | R26: -36017.841 | S26: 216403.71 | T26: 635275.78
B27: Mobiliario | C27: =TESORERIA!C14 -> 32000 | E27: Pasivo | F27: =F28+F30 -> 104916.78 | J27: Mobiliario | K27: =TESORERIA!C14 -> 32000 | M27: Pasivo | N27: =N28+N30 -> 0 | Q27: Pasivo | R27: 204837.48 | S27: 104916.78 | T27: 0
B28: Amortización acum. | C28: =-('CUENTA DE PYG'!D35+'CUENTA DE PYG'!L11) -> -87720 | E28: Largo Plazo | F28: =F29 -> 0 | J28: Amortización acum. | K28: =-('CUENTA DE PYG'!D35+'CUENTA DE PYG'!L11+'CUENTA DE PYG'!D11) -> -131580 | M28: Largo Plazo | N28: =N29 -> 0 | Q28: Largo Plazo | R28: 104916.78 | S28: 0 | T28: 0
B29: Corriente | C29: =C30+C31+C32+C33 -> 262018.21 | E29: Capital pendiente | F29: =PRESTAMO!I37 -> 0 | J29: Corriente | K29: =K30+K31+K32 -> 836237.21 | M29: Capital pendiente | N29: 0 | Q29: Capital pendiente | R29: 104916.78 | S29: 0 | T29: 0
B30: Existente | C30: 0 | E30: Corto Plazo | F30: =F31 -> 104916.78 | J30: Existente | K30: 0 | M30: Corto Plazo | N30: =N31 -> 0 | Q30: Corto Plazo | R30: 99920.696 | S30: 104916.78 | T30: 0
B31: Realizable | C31: 0 | E31: Capital pendiente | F31: =PRESTAMO!I36 -> 104916.78 | J31: Realizable | K31: 0 | M31: Capital pendiente | N31: 0 | Q31: Capital pendiente | R31: 99920.696 | S31: 104916.78 | T31: 0
B32: Disponible | C32: =TESORERIA!P27 -> 262018.21 | J32: Disponible | K32: =TESORERIA!Q27 -> 836237.21
B34: TOTAL | C34: =C23+C29 -> 785302.66 | E34: TOTAL | F34: =F27+F23 -> 785302.66 | J34: TOTAL | K34: =K23+K29 -> 1315661.7 | M34: TOTAL | N34: =N27+N23 -> 1315661.7 | Q34: TOTAL | R34: 668819.64 | S34: 785302.66 | T34: 1315661.7
B43: Activo
B44: No corriente | C44: 567144.45
B45: Página web | C45: 4.45
B46: Talleres | C46: 561000
B47: Maquinaria | C47: 18000
B48: Mobiliario | C48: 32000
B49: Amortización acum. | C49: -43860
B50: Corriente | C50: 101675.19
B51: Existente | C51: 0
...

Sheet ANALISIS DE LA INVERSION
C4: A | D4: Desembolso inicial | E4: =-'VENTA Y GASTO'!B34 -> -611004.45
C5: Q1(cash flow 1) | D5: Flujo AÑO 1 | E5: =TESORERIA!C26 -> 101675.19
C6: Q2(cash flow 2) | D6: Flujo AÑO 2 | E6: =TESORERIA!P26 -> 160343.02
C7: Q3(cash flow 3) | D7: Flujo AÑO 3 | E7: =TESORERIA!Q26 -> 574219
C8: k | D8: Coste del dinero | E8: 0.013753125
C9: TIR | E9: =IRR(E4:E7) -> 0.13185209
C10: VAN | E10: {=NPV(E8,E5:E7)+E4} -> 196477.41
B13: Calculamos el valor actual neto y la tasa interna de rentabilidad de la inversión del dinero, teniendo en cuenta el desembolso inicial calculado en la primera pagina de la excell, hallando la resta del prestamo y el capital social invertido por los socios y los los gastos de apertura. Visualizando estas cuentas podemos afirmar que el proyecto empresarial es beneficioso ya que el VAN>0 y la TIR>k ***k calculadlo según el WACC y tomando el costo sobre los intereses como 0.

Sheet AMORTIZACION
C3: Importe | D3: % Amortización anual | E3: Amortización año 1 | F3: Amortización año 2 | G3: Amortización año 3 | H3: TOTAL AÑO 1 | I3: TOTAL AÑO 2 | J3: TOTAL AÑO 3
B4: Talleres | C4: ='VENTA Y GASTO'!B20 -> 561000 | D4: 0.02 | E4: =C4*D4 -> 11220 | F4: =C4*D4 -> 11220 | G4: =C4*D4 -> 11220 | H4: =C4-E4 -> 549780 | I4: =H4-F4 -> 538560 | J4: =I4-G4 -> 527340
B5: Maquinaria | C5: ='VENTA Y GASTO'!B24 -> 18000 | D5: 0.1 | E5: =C5*D5 -> 1800 | F5: =C5*D5 -> 1800 | G5: =C5*D5 -> 1800 | H5: =C5-E5 -> 16200 | I5: =H5-F5 -> 14400 | J5: =I5-G5 -> 12600
B6: Mobiliario | C6: ='VENTA Y GASTO'!B25 -> 32000 | D6: 0.05 | E6: =C6*D6 -> 1600 | F6: =C6*D6 -> 1600 | G6: =C6*D6 -> 1600 | H6: =C6-E6 -> 30400 | I6: =H6-F6 -> 28800 | J6: =I6-G6 -> 27200
C7: =SUM(C4:C6) -> 611000 | E7: =SUM(E4:E6) -> 14620 | F7: =SUM(F4:F6) -> 14620 | G7: =SUM(G4:G6) -> 14620 | J7: =SUM(J4:J6) -> 567140
B10: AMORTIZACION TOTAL : | C10: =C7-J7 -> 43860 | E10: Consideramos que el taller dura 50 años, la maquinaria 10 y el mobiliario 20

Sheet ANÁLISIS ECONÓMICO FINANCIERO
B2: RATIOS FINANCIEROS | D2: Inicio | E2: Año 1 | F2: Año 2 | G2: Año 3
B3: Apalancamiento Financiero | D3: =BALANCES!C15/BALANCES!F4 -> 1.6 | E3: =BALANCES!K15/BALANCES!N4 -> 1.4414771 | F3: =BALANCES!C23/BALANCES!F23 -> 0.76909952 | G3: =BALANCES!K23/BALANCES!N23 -> 0.36439798
B4: Endeudamiento | D4: =BALANCES!F8/BALANCES!F4 -> 0.6 | E4: =BALANCES!N8/BALANCES!N4 -> 0.44147706 | F4: =BALANCES!F27/BALANCES!F23 -> 0.15420189 | G4: =BALANCES!N27/BALANCES!N23 -> 0
B5: Solvencia | D5: =BALANCES!C15/BALANCES!F8 -> 2.6666667 | E5: =BALANCES!K15/BALANCES!N8 -> 3.2651233 | F5: =BALANCES!C34/BALANCES!F27 -> 7.485005 | G5: ∞
B6: Liquidez | D6: =BALANCES!C10/BALANCES!F11 -> 1.9860293 | E6: =BALANCES!K10/BALANCES!N11 -> 1.0175589 | F6: =BALANCES!C29/BALANCES!F30 -> 2.4973908 | G6: ∞
B7: Tesorería | D7: =BALANCES!C13/BALANCES!F11 -> 1.9860293 | E7: =BALANCES!K13/BALANCES!N11 -> 1.0175589 | F7: =BALANCES!C32/BALANCES!F30 -> 2.4973908 | G7: ∞
B8: Disponibilidad | D8: =BALANCES!C13/BALANCES!F11 -> 1.9860293 | E8: =BALANCES!K13/BALANCES!N11 -> 1.0175589 | F8: =BALANCES!C32/BALANCES!F30 -> 2.4973908 | G8: ∞
B9: Fondo de maniobra | D9: =BALANCES!C10-BALANCES!F11 -> 93833.031 | E9: =BALANCES!K10-BALANCES!N11 -> 1754.4942 | F9: =BALANCES!C29-BALANCES!F30 -> 157101.42 | G9: =BALANCES!K29-BALANCES!N30 -> 836237.21
B10: Rentabilidad financiera (ROE) | D10: =BALANCES!F7/(BALANCES!F6+BALANCES!F5)*100 -> 0 | E10: =BALANCES!N7/(BALANCES!N6+BALANCES!N5)*100 -> -7.2035681 | F10: =BALANCES!F26/(BALANCES!F25+BALANCES!F24)*100 -> 46.640525 | G10: =BALANCES!N26/(BALANCES!N25+BALANCES!N24)*100 -> 93.369925
B11: Rentabilidad financiera (BN/PN) | D11: =BALANCES!F7/BALANCES!F4 -> 0 | E11: =BALANCES!N7/BALANCES!N4 -> -0.077627641 | F11: =BALANCES!F26/BALANCES!F23 -> 0.31806027 | G11: =BALANCES!N26/BALANCES!N23 -> 0.4828565
B13: RATIOS ECONOMICOS | E13: Año 1 | F13: Año 2 | G13: Año 3
B14: EBITDA | E14: =E15+'CUENTA DE PYG'!D11 -> 20395.55 | F14: =F15+'CUENTA DE PYG'!L11 -> 340193.5 | G14: ='CUENTA DE PYG'!F27-'CUENTA DE PYG'!F29+'CUENTA DE PYG'!D35 -> 893693.5
B15: Beneficio neto (BAIT) | E15: ='CUENTA DE PYG'!F21+'CUENTA DE PYG'!D20+'CUENTA DE PYG'!D17 -> -23464.45 | F15: ='CUENTA DE PYG'!N21+'CUENTA DE PYG'!L20+'CUENTA DE PYG'!L17 -> 296333.5 | G15: ='CUENTA DE PYG'!F45+'CUENTA DE PYG'!D44+'CUENTA DE PYG'!D41 -> 849833.5
B16: Rentabilidad económica (ROI) | E16: ='CUENTA DE PYG'!F13/BALANCES!C15 -> -0.029330563 | F16: ='CUENTA DE PYG'!N13/BALANCES!C34 -> 0.37734942 | G16: ='CUENTA DE PYG'!F37/BALANCES!K34 -> 0.64593621
B17: Rentabilidad de ventas | E17: =E15/'VENTA Y GASTO'!L10 -> -0.010899503 | F17: =F15/'VENTA Y GASTO'!M10 -> 0.097838583 | G17: =G15/'VENTA Y GASTO'!N10 -> 0.18794973
B18: Rotación activo | E18: =BALANCES!N7/BALANCES!K15 -> -0.053852845 | F18: =BALANCES!F26/BALANCES!C34 -> 0.27556728 | G18: =BALANCES!N26/BALANCES!K34 -> 0.4828565
